[2019-03-30 06:11:17,148]WARNING:file_cache is unavailable when using oauth2client >= 4.0.0 or google-auth
Traceback (most recent call last):
  File "/home/liu/.local/lib/python3.6/site-packages/googleapiclient/discovery_cache/__init__.py", line 36, in autodetect
    from google.appengine.api import memcache
ModuleNotFoundError: No module named 'google.appengine'

During handling of the above exception, another exception occurred:

Traceback (most recent call last):
  File "/home/liu/.local/lib/python3.6/site-packages/googleapiclient/discovery_cache/file_cache.py", line 33, in <module>
    from oauth2client.contrib.locked_file import LockedFile
ModuleNotFoundError: No module named 'oauth2client.contrib.locked_file'

During handling of the above exception, another exception occurred:

Traceback (most recent call last):
  File "/home/liu/.local/lib/python3.6/site-packages/googleapiclient/discovery_cache/file_cache.py", line 37, in <module>
    from oauth2client.locked_file import LockedFile
ModuleNotFoundError: No module named 'oauth2client.locked_file'

During handling of the above exception, another exception occurred:

Traceback (most recent call last):
  File "/home/liu/.local/lib/python3.6/site-packages/googleapiclient/discovery_cache/__init__.py", line 41, in autodetect
    from . import file_cache
  File "/home/liu/.local/lib/python3.6/site-packages/googleapiclient/discovery_cache/file_cache.py", line 41, in <module>
    'file_cache is unavailable when using oauth2client >= 4.0.0 or google-auth')
ImportError: file_cache is unavailable when using oauth2client >= 4.0.0 or google-auth
[2019-03-30 06:11:17,150]INFO:URL being requested: GET https://www.googleapis.com/discovery/v1/apis/calendar/v3/rest
[2019-03-30 06:13:22,437]WARNING:file_cache is unavailable when using oauth2client >= 4.0.0 or google-auth
Traceback (most recent call last):
  File "/home/liu/.local/lib/python3.6/site-packages/googleapiclient/discovery_cache/__init__.py", line 36, in autodetect
    from google.appengine.api import memcache
ModuleNotFoundError: No module named 'google.appengine'

During handling of the above exception, another exception occurred:

Traceback (most recent call last):
  File "/home/liu/.local/lib/python3.6/site-packages/googleapiclient/discovery_cache/file_cache.py", line 33, in <module>
    from oauth2client.contrib.locked_file import LockedFile
ModuleNotFoundError: No module named 'oauth2client.contrib.locked_file'

During handling of the above exception, another exception occurred:

Traceback (most recent call last):
  File "/home/liu/.local/lib/python3.6/site-packages/googleapiclient/discovery_cache/file_cache.py", line 37, in <module>
    from oauth2client.locked_file import LockedFile
ModuleNotFoundError: No module named 'oauth2client.locked_file'

During handling of the above exception, another exception occurred:

Traceback (most recent call last):
  File "/home/liu/.local/lib/python3.6/site-packages/googleapiclient/discovery_cache/__init__.py", line 41, in autodetect
    from . import file_cache
  File "/home/liu/.local/lib/python3.6/site-packages/googleapiclient/discovery_cache/file_cache.py", line 41, in <module>
    'file_cache is unavailable when using oauth2client >= 4.0.0 or google-auth')
ImportError: file_cache is unavailable when using oauth2client >= 4.0.0 or google-auth
[2019-03-30 06:13:22,438]INFO:URL being requested: GET https://www.googleapis.com/discovery/v1/apis/calendar/v3/rest
[2019-03-30 06:13:22,641]INFO:URL being requested: POST https://www.googleapis.com/calendar/v3/calendars/primary/events?alt=json
[2019-03-30 06:13:22,691]INFO:Refreshing due to a 401 (attempt 1/2)
[2019-03-30 06:13:22,692]INFO:Refreshing access_token
